[2023-11-09T19:54:28.522+0000] {taskinstance.py:1159} INFO - Dependencies all met for dep_context=non-requeueable deps ti=<TaskInstance: bananinha.passo_2 manual__2023-11-09T19:54:27.115746+00:00 [queued]>
[2023-11-09T19:54:28.527+0000] {taskinstance.py:1159} INFO - Dependencies all met for dep_context=requeueable deps ti=<TaskInstance: bananinha.passo_2 manual__2023-11-09T19:54:27.115746+00:00 [queued]>
[2023-11-09T19:54:28.527+0000] {taskinstance.py:1361} INFO - Starting attempt 1 of 1
[2023-11-09T19:54:28.536+0000] {taskinstance.py:1382} INFO - Executing <Task(PythonOperator): passo_2> on 2023-11-09 19:54:27.115746+00:00
[2023-11-09T19:54:28.540+0000] {standard_task_runner.py:57} INFO - Started process 3504 to run task
[2023-11-09T19:54:28.542+0000] {standard_task_runner.py:84} INFO - Running: ['***', 'tasks', 'run', 'bananinha', 'passo_2', 'manual__2023-11-09T19:54:27.115746+00:00', '--job-id', '56', '--raw', '--subdir', 'DAGS_FOLDER/passos.py', '--cfg-path', '/tmp/tmp96klrwa4']
[2023-11-09T19:54:28.543+0000] {standard_task_runner.py:85} INFO - Job 56: Subtask passo_2
[2023-11-09T19:54:28.570+0000] {task_command.py:415} INFO - Running <TaskInstance: bananinha.passo_2 manual__2023-11-09T19:54:27.115746+00:00 [running]> on host a23ad50e55eb
[2023-11-09T19:54:28.619+0000] {taskinstance.py:1660} INFO - Exporting env vars: AIRFLOW_CTX_DAG_OWNER='***' AIRFLOW_CTX_DAG_ID='bananinha' AIRFLOW_CTX_TASK_ID='passo_2' AIRFLOW_CTX_EXECUTION_DATE='2023-11-09T19:54:27.115746+00:00' AIRFLOW_CTX_TRY_NUMBER='1' AIRFLOW_CTX_DAG_RUN_ID='manual__2023-11-09T19:54:27.115746+00:00'
[2023-11-09T19:54:28.620+0000] {taskinstance.py:1943} ERROR - Task failed with exception
Traceback (most recent call last):
  File "/home/airflow/.local/lib/python3.10/site-packages/airflow/operators/python.py", line 192, in execute
    return_value = self.execute_callable()
  File "/home/airflow/.local/lib/python3.10/site-packages/airflow/operators/python.py", line 209, in execute_callable
    return self.python_callable(*self.op_args, **self.op_kwargs)
  File "/opt/airflow/dags/passos.py", line 12, in passo_2_func
    last_message = context["ti"].xcom_pull(
  File "/home/airflow/.local/lib/python3.10/site-packages/airflow/utils/session.py", line 77, in wrapper
    return func(*args, session=session, **kwargs)
TypeError: TaskInstance.xcom_pull() got an unexpected keyword argument 'task_id'
[2023-11-09T19:54:28.625+0000] {taskinstance.py:1400} INFO - Marking task as FAILED. dag_id=bananinha, task_id=passo_2, execution_date=20231109T195427, start_date=20231109T195428, end_date=20231109T195428
[2023-11-09T19:54:28.631+0000] {standard_task_runner.py:104} ERROR - Failed to execute job 56 for task passo_2 (TaskInstance.xcom_pull() got an unexpected keyword argument 'task_id'; 3504)
[2023-11-09T19:54:28.674+0000] {local_task_job_runner.py:228} INFO - Task exited with return code 1
[2023-11-09T19:54:28.687+0000] {taskinstance.py:2784} INFO - 0 downstream tasks scheduled from follow-on schedule check
