[2023-11-09T17:19:28.266+0000] {taskinstance.py:1159} INFO - Dependencies all met for dep_context=non-requeueable deps ti=<TaskInstance: query_scraper.prepare manual__2023-11-09T17:19:26.510251+00:00 [queued]>
[2023-11-09T17:19:28.275+0000] {taskinstance.py:1159} INFO - Dependencies all met for dep_context=requeueable deps ti=<TaskInstance: query_scraper.prepare manual__2023-11-09T17:19:26.510251+00:00 [queued]>
[2023-11-09T17:19:28.276+0000] {taskinstance.py:1361} INFO - Starting attempt 1 of 1
[2023-11-09T17:19:28.285+0000] {taskinstance.py:1382} INFO - Executing <Task(PythonOperator): prepare> on 2023-11-09 17:19:26.510251+00:00
[2023-11-09T17:19:28.292+0000] {standard_task_runner.py:57} INFO - Started process 161 to run task
[2023-11-09T17:19:28.294+0000] {standard_task_runner.py:84} INFO - Running: ['***', 'tasks', 'run', 'query_scraper', 'prepare', 'manual__2023-11-09T17:19:26.510251+00:00', '--job-id', '3', '--raw', '--subdir', 'DAGS_FOLDER/dag_definitions.py', '--cfg-path', '/tmp/tmpbt_btmec']
[2023-11-09T17:19:28.295+0000] {standard_task_runner.py:85} INFO - Job 3: Subtask prepare
[2023-11-09T17:19:28.336+0000] {task_command.py:415} INFO - Running <TaskInstance: query_scraper.prepare manual__2023-11-09T17:19:26.510251+00:00 [running]> on host 3d4248894d68
[2023-11-09T17:19:28.405+0000] {taskinstance.py:1660} INFO - Exporting env vars: AIRFLOW_CTX_DAG_OWNER='***' AIRFLOW_CTX_DAG_ID='query_scraper' AIRFLOW_CTX_TASK_ID='prepare' AIRFLOW_CTX_EXECUTION_DATE='2023-11-09T17:19:26.510251+00:00' AIRFLOW_CTX_TRY_NUMBER='1' AIRFLOW_CTX_DAG_RUN_ID='manual__2023-11-09T17:19:26.510251+00:00'
[2023-11-09T17:19:28.407+0000] {logger.py:18} INFO - Creating path
[2023-11-09T17:19:28.408+0000] {taskinstance.py:1943} ERROR - Task failed with exception
Traceback (most recent call last):
  File "/home/airflow/.local/lib/python3.10/site-packages/airflow/operators/python.py", line 192, in execute
    return_value = self.execute_callable()
  File "/home/airflow/.local/lib/python3.10/site-packages/airflow/operators/python.py", line 209, in execute_callable
    return self.python_callable(*self.op_args, **self.op_kwargs)
  File "/opt/airflow/dags/task_definitions.py", line 74, in prepare
    output_path = make_path(
  File "/opt/airflow/dags/resources/constructors.py", line 20, in make_path
    locale.setlocale(locale.LC_ALL, 'pt_BR.UTF-8')
  File "/usr/local/lib/python3.10/locale.py", line 620, in setlocale
    return _setlocale(category, locale)
locale.Error: unsupported locale setting
[2023-11-09T17:19:28.415+0000] {taskinstance.py:1400} INFO - Marking task as FAILED. dag_id=query_scraper, task_id=prepare, execution_date=20231109T171926, start_date=20231109T171928, end_date=20231109T171928
[2023-11-09T17:19:28.430+0000] {standard_task_runner.py:104} ERROR - Failed to execute job 3 for task prepare (unsupported locale setting; 161)
[2023-11-09T17:19:28.466+0000] {local_task_job_runner.py:228} INFO - Task exited with return code 1
[2023-11-09T17:19:28.485+0000] {taskinstance.py:2784} INFO - 0 downstream tasks scheduled from follow-on schedule check
