[2023-11-09T19:39:34.201+0000] {taskinstance.py:1159} INFO - Dependencies all met for dep_context=non-requeueable deps ti=<TaskInstance: query_scraper.validate_item_descriptions manual__2023-11-09T18:53:40.251543+00:00 [queued]>
[2023-11-09T19:39:34.207+0000] {taskinstance.py:1159} INFO - Dependencies all met for dep_context=requeueable deps ti=<TaskInstance: query_scraper.validate_item_descriptions manual__2023-11-09T18:53:40.251543+00:00 [queued]>
[2023-11-09T19:39:34.208+0000] {taskinstance.py:1361} INFO - Starting attempt 1 of 1
[2023-11-09T19:39:34.214+0000] {taskinstance.py:1382} INFO - Executing <Task(PythonOperator): validate_item_descriptions> on 2023-11-09 18:53:40.251543+00:00
[2023-11-09T19:39:34.220+0000] {standard_task_runner.py:57} INFO - Started process 3101 to run task
[2023-11-09T19:39:34.222+0000] {standard_task_runner.py:84} INFO - Running: ['***', 'tasks', 'run', 'query_scraper', 'validate_item_descriptions', 'manual__2023-11-09T18:53:40.251543+00:00', '--job-id', '46', '--raw', '--subdir', 'DAGS_FOLDER/dag_definitions.py', '--cfg-path', '/tmp/tmp9bnesd0v']
[2023-11-09T19:39:34.224+0000] {standard_task_runner.py:85} INFO - Job 46: Subtask validate_item_descriptions
[2023-11-09T19:39:34.250+0000] {task_command.py:415} INFO - Running <TaskInstance: query_scraper.validate_item_descriptions manual__2023-11-09T18:53:40.251543+00:00 [running]> on host a23ad50e55eb
[2023-11-09T19:39:34.295+0000] {taskinstance.py:1660} INFO - Exporting env vars: AIRFLOW_CTX_DAG_OWNER='***' AIRFLOW_CTX_DAG_ID='query_scraper' AIRFLOW_CTX_TASK_ID='validate_item_descriptions' AIRFLOW_CTX_EXECUTION_DATE='2023-11-09T18:53:40.251543+00:00' AIRFLOW_CTX_TRY_NUMBER='1' AIRFLOW_CTX_DAG_RUN_ID='manual__2023-11-09T18:53:40.251543+00:00'
[2023-11-09T19:39:34.338+0000] {taskinstance.py:1943} ERROR - Task failed with exception
Traceback (most recent call last):
  File "/home/airflow/.local/lib/python3.10/site-packages/airflow/operators/python.py", line 192, in execute
    return_value = self.execute_callable()
  File "/home/airflow/.local/lib/python3.10/site-packages/airflow/operators/python.py", line 209, in execute_callable
    return self.python_callable(*self.op_args, **self.op_kwargs)
  File "/opt/airflow/dags/task_definitions.py", line 120, in validade_collected_items
    data_collected = self._filter_valid_items(data_collected)
  File "/opt/airflow/dags/task_definitions.py", line 179, in _filter_valid_items
    items = items.drop_duplicates('url', axis=0)
  File "/home/airflow/.local/lib/python3.10/site-packages/pandas/util/_decorators.py", line 311, in wrapper
    return func(*args, **kwargs)
TypeError: DataFrame.drop_duplicates() got an unexpected keyword argument 'axis'
[2023-11-09T19:39:34.343+0000] {taskinstance.py:1400} INFO - Marking task as FAILED. dag_id=query_scraper, task_id=validate_item_descriptions, execution_date=20231109T185340, start_date=20231109T193934, end_date=20231109T193934
[2023-11-09T19:39:34.350+0000] {standard_task_runner.py:104} ERROR - Failed to execute job 46 for task validate_item_descriptions (DataFrame.drop_duplicates() got an unexpected keyword argument 'axis'; 3101)
[2023-11-09T19:39:34.394+0000] {local_task_job_runner.py:228} INFO - Task exited with return code 1
[2023-11-09T19:39:34.409+0000] {taskinstance.py:2784} INFO - 0 downstream tasks scheduled from follow-on schedule check
