[2023-11-09T17:39:18.328+0000] {taskinstance.py:1159} INFO - Dependencies all met for dep_context=non-requeueable deps ti=<TaskInstance: query_scraper.collect_items manual__2023-11-09T17:19:26.510251+00:00 [queued]>
[2023-11-09T17:39:18.333+0000] {taskinstance.py:1159} INFO - Dependencies all met for dep_context=requeueable deps ti=<TaskInstance: query_scraper.collect_items manual__2023-11-09T17:19:26.510251+00:00 [queued]>
[2023-11-09T17:39:18.333+0000] {taskinstance.py:1361} INFO - Starting attempt 1 of 1
[2023-11-09T17:39:18.348+0000] {taskinstance.py:1382} INFO - Executing <Task(PythonOperator): collect_items> on 2023-11-09 17:19:26.510251+00:00
[2023-11-09T17:39:18.352+0000] {standard_task_runner.py:57} INFO - Started process 123 to run task
[2023-11-09T17:39:18.353+0000] {standard_task_runner.py:84} INFO - Running: ['***', 'tasks', 'run', 'query_scraper', 'collect_items', 'manual__2023-11-09T17:19:26.510251+00:00', '--job-id', '12', '--raw', '--subdir', 'DAGS_FOLDER/dag_definitions.py', '--cfg-path', '/tmp/tmpp5jb3itg']
[2023-11-09T17:39:18.355+0000] {standard_task_runner.py:85} INFO - Job 12: Subtask collect_items
[2023-11-09T17:39:18.381+0000] {task_command.py:415} INFO - Running <TaskInstance: query_scraper.collect_items manual__2023-11-09T17:19:26.510251+00:00 [running]> on host 273cd10b3230
[2023-11-09T17:39:18.421+0000] {taskinstance.py:1660} INFO - Exporting env vars: AIRFLOW_CTX_DAG_OWNER='***' AIRFLOW_CTX_DAG_ID='query_scraper' AIRFLOW_CTX_TASK_ID='collect_items' AIRFLOW_CTX_EXECUTION_DATE='2023-11-09T17:19:26.510251+00:00' AIRFLOW_CTX_TRY_NUMBER='1' AIRFLOW_CTX_DAG_RUN_ID='manual__2023-11-09T17:19:26.510251+00:00'
[2023-11-09T17:39:18.443+0000] {taskinstance.py:1943} ERROR - Task failed with exception
Traceback (most recent call last):
  File "/home/airflow/.local/lib/python3.10/site-packages/airflow/operators/python.py", line 192, in execute
    return_value = self.execute_callable()
  File "/home/airflow/.local/lib/python3.10/site-packages/airflow/operators/python.py", line 209, in execute_callable
    return self.python_callable(*self.op_args, **self.op_kwargs)
  File "/opt/airflow/dags/task_definitions.py", line 96, in collect
    self.info(f'Searching query: {query}')
NameError: name 'query' is not defined
[2023-11-09T17:39:18.450+0000] {taskinstance.py:1400} INFO - Marking task as FAILED. dag_id=query_scraper, task_id=collect_items, execution_date=20231109T171926, start_date=20231109T173918, end_date=20231109T173918
[2023-11-09T17:39:18.455+0000] {standard_task_runner.py:104} ERROR - Failed to execute job 12 for task collect_items (name 'query' is not defined; 123)
[2023-11-09T17:39:18.485+0000] {local_task_job_runner.py:228} INFO - Task exited with return code 1
[2023-11-09T17:39:18.516+0000] {taskinstance.py:2784} INFO - 0 downstream tasks scheduled from follow-on schedule check
