[2023-11-09T17:39:46.835+0000] {taskinstance.py:1159} INFO - Dependencies all met for dep_context=non-requeueable deps ti=<TaskInstance: query_scraper.collect_items manual__2023-11-09T17:19:26.510251+00:00 [queued]>
[2023-11-09T17:39:46.840+0000] {taskinstance.py:1159} INFO - Dependencies all met for dep_context=requeueable deps ti=<TaskInstance: query_scraper.collect_items manual__2023-11-09T17:19:26.510251+00:00 [queued]>
[2023-11-09T17:39:46.840+0000] {taskinstance.py:1361} INFO - Starting attempt 2 of 2
[2023-11-09T17:39:46.859+0000] {taskinstance.py:1382} INFO - Executing <Task(PythonOperator): collect_items> on 2023-11-09 17:19:26.510251+00:00
[2023-11-09T17:39:46.864+0000] {standard_task_runner.py:57} INFO - Started process 137 to run task
[2023-11-09T17:39:46.865+0000] {standard_task_runner.py:84} INFO - Running: ['***', 'tasks', 'run', 'query_scraper', 'collect_items', 'manual__2023-11-09T17:19:26.510251+00:00', '--job-id', '13', '--raw', '--subdir', 'DAGS_FOLDER/dag_definitions.py', '--cfg-path', '/tmp/tmp3t1_skrm']
[2023-11-09T17:39:46.867+0000] {standard_task_runner.py:85} INFO - Job 13: Subtask collect_items
[2023-11-09T17:39:46.893+0000] {task_command.py:415} INFO - Running <TaskInstance: query_scraper.collect_items manual__2023-11-09T17:19:26.510251+00:00 [running]> on host 273cd10b3230
[2023-11-09T17:39:46.934+0000] {taskinstance.py:1660} INFO - Exporting env vars: AIRFLOW_CTX_DAG_OWNER='***' AIRFLOW_CTX_DAG_ID='query_scraper' AIRFLOW_CTX_TASK_ID='collect_items' AIRFLOW_CTX_EXECUTION_DATE='2023-11-09T17:19:26.510251+00:00' AIRFLOW_CTX_TRY_NUMBER='2' AIRFLOW_CTX_DAG_RUN_ID='manual__2023-11-09T17:19:26.510251+00:00'
[2023-11-09T17:39:46.955+0000] {taskinstance.py:1943} ERROR - Task failed with exception
Traceback (most recent call last):
  File "/home/airflow/.local/lib/python3.10/site-packages/airflow/operators/python.py", line 192, in execute
    return_value = self.execute_callable()
  File "/home/airflow/.local/lib/python3.10/site-packages/airflow/operators/python.py", line 209, in execute_callable
    return self.python_callable(*self.op_args, **self.op_kwargs)
  File "/opt/airflow/dags/task_definitions.py", line 96, in collect
    self.info(f'Searching query: {query}')
NameError: name 'query' is not defined
[2023-11-09T17:39:46.961+0000] {taskinstance.py:1400} INFO - Marking task as FAILED. dag_id=query_scraper, task_id=collect_items, execution_date=20231109T171926, start_date=20231109T173946, end_date=20231109T173946
[2023-11-09T17:39:46.967+0000] {standard_task_runner.py:104} ERROR - Failed to execute job 13 for task collect_items (name 'query' is not defined; 137)
[2023-11-09T17:39:46.997+0000] {local_task_job_runner.py:228} INFO - Task exited with return code 1
[2023-11-09T17:39:47.027+0000] {taskinstance.py:2784} INFO - 0 downstream tasks scheduled from follow-on schedule check
