[2023-11-09T19:34:17.000+0000] {taskinstance.py:1159} INFO - Dependencies all met for dep_context=non-requeueable deps ti=<TaskInstance: query_scraper.prepare manual__2023-11-09T18:53:40.251543+00:00 [queued]>
[2023-11-09T19:34:17.005+0000] {taskinstance.py:1159} INFO - Dependencies all met for dep_context=requeueable deps ti=<TaskInstance: query_scraper.prepare manual__2023-11-09T18:53:40.251543+00:00 [queued]>
[2023-11-09T19:34:17.006+0000] {taskinstance.py:1361} INFO - Starting attempt 2 of 2
[2023-11-09T19:34:17.013+0000] {taskinstance.py:1382} INFO - Executing <Task(PythonOperator): prepare> on 2023-11-09 18:53:40.251543+00:00
[2023-11-09T19:34:17.018+0000] {standard_task_runner.py:57} INFO - Started process 706 to run task
[2023-11-09T19:34:17.020+0000] {standard_task_runner.py:84} INFO - Running: ['***', 'tasks', 'run', 'query_scraper', 'prepare', 'manual__2023-11-09T18:53:40.251543+00:00', '--job-id', '42', '--raw', '--subdir', 'DAGS_FOLDER/dag_definitions.py', '--cfg-path', '/tmp/tmpwd32atez']
[2023-11-09T19:34:17.022+0000] {standard_task_runner.py:85} INFO - Job 42: Subtask prepare
[2023-11-09T19:34:17.049+0000] {task_command.py:415} INFO - Running <TaskInstance: query_scraper.prepare manual__2023-11-09T18:53:40.251543+00:00 [running]> on host a23ad50e55eb
[2023-11-09T19:34:17.094+0000] {taskinstance.py:1660} INFO - Exporting env vars: AIRFLOW_CTX_DAG_OWNER='***' AIRFLOW_CTX_DAG_ID='query_scraper' AIRFLOW_CTX_TASK_ID='prepare' AIRFLOW_CTX_EXECUTION_DATE='2023-11-09T18:53:40.251543+00:00' AIRFLOW_CTX_TRY_NUMBER='2' AIRFLOW_CTX_DAG_RUN_ID='manual__2023-11-09T18:53:40.251543+00:00'
[2023-11-09T19:34:17.095+0000] {logger.py:18} INFO - Creating path
[2023-11-09T19:34:17.096+0000] {logging_mixin.py:151} INFO - Create ./data_output/STZ//2023/novembro/2023_11_09 folder
[2023-11-09T19:34:17.096+0000] {logger.py:18} INFO - Reading csv file
[2023-11-09T19:34:17.097+0000] {taskinstance.py:1943} ERROR - Task failed with exception
Traceback (most recent call last):
  File "/home/airflow/.local/lib/python3.10/site-packages/airflow/operators/python.py", line 192, in execute
    return_value = self.execute_callable()
  File "/home/airflow/.local/lib/python3.10/site-packages/airflow/operators/python.py", line 209, in execute_callable
    return self.python_callable(*self.op_args, **self.op_kwargs)
  File "/opt/airflow/dags/task_definitions.py", line 79, in prepare
    df = pd.read_csv("dags/data_input/querys.csv", dtype=str)
  File "/home/airflow/.local/lib/python3.10/site-packages/pandas/util/_decorators.py", line 311, in wrapper
    return func(*args, **kwargs)
  File "/home/airflow/.local/lib/python3.10/site-packages/pandas/io/parsers/readers.py", line 586, in read_csv
    return _read(filepath_or_buffer, kwds)
  File "/home/airflow/.local/lib/python3.10/site-packages/pandas/io/parsers/readers.py", line 482, in _read
    parser = TextFileReader(filepath_or_buffer, **kwds)
  File "/home/airflow/.local/lib/python3.10/site-packages/pandas/io/parsers/readers.py", line 811, in __init__
    self._engine = self._make_engine(self.engine)
  File "/home/airflow/.local/lib/python3.10/site-packages/pandas/io/parsers/readers.py", line 1040, in _make_engine
    return mapping[engine](self.f, **self.options)  # type: ignore[call-arg]
  File "/home/airflow/.local/lib/python3.10/site-packages/pandas/io/parsers/c_parser_wrapper.py", line 51, in __init__
    self._open_handles(src, kwds)
  File "/home/airflow/.local/lib/python3.10/site-packages/pandas/io/parsers/base_parser.py", line 222, in _open_handles
    self.handles = get_handle(
  File "/home/airflow/.local/lib/python3.10/site-packages/pandas/io/common.py", line 702, in get_handle
    handle = open(
FileNotFoundError: [Errno 2] No such file or directory: 'dags/data_input/querys.csv'
[2023-11-09T19:34:17.103+0000] {taskinstance.py:1400} INFO - Marking task as FAILED. dag_id=query_scraper, task_id=prepare, execution_date=20231109T185340, start_date=20231109T193417, end_date=20231109T193417
[2023-11-09T19:34:17.111+0000] {standard_task_runner.py:104} ERROR - Failed to execute job 42 for task prepare ([Errno 2] No such file or directory: 'dags/data_input/querys.csv'; 706)
[2023-11-09T19:34:17.151+0000] {local_task_job_runner.py:228} INFO - Task exited with return code 1
[2023-11-09T19:34:17.168+0000] {taskinstance.py:2784} INFO - 0 downstream tasks scheduled from follow-on schedule check
